File: c9dee2b0-6919-4adf-8578-31db090a148b.json
Error: Update application failed
Timestamp: 2025-07-18T22:49:02.333531
Stack trace:
Traceback (most recent call last):
  File "/home/runner/work/subtitle-manager/subtitle-manager/doc_update_manager.py", line 447, in _process_single_file_safely
    self.process_update_file_data(update_file, update_data)
  File "/home/runner/work/subtitle-manager/subtitle-manager/doc_update_manager.py", line 495, in process_update_file_data
    raise Exception("Update application failed")
Exception: Update application failed
